Workbook
Name campo: Reporte!$C$3
Name company: Reporte!$C$4
Name Departamento: Reporte!$C$6
Name Logdate: Reporte!$C$12
Name NomId: Reporte!$C$11
Name NomOd: Reporte!$C$10
Name Pais: Reporte!$C$7
Name Path: Reporte!$C$28
Name Pozo: Reporte!$C$2
Name Top: OFFSET(Tabla!#REF!,0,0,countara(Tabla!$L:$L),1)

Sheet Tabla
A1: Well | B1: Field | C1: Country | D1: State Province | E1: Company | F1: Service Company | G1: Log Date | H1: Nom OD | I1: Nom ID | J1: Nom Thicknes | K1: Join | L1: Top Body | M1: Bottom Body | N1: Body Length | O1: Min. Diam. Ins. | P1: Min. Diam. Depth | Q1: Max. Wall Ins. | R1: Max. Loss % | S1: Max. Loss Depth | T1: Mean Wall Ins. | U1: Max. Pen. Ins | V1: Max. Pen. Depth | W1: Min. Wall Ins. | X1: Max. Pen. % | Y1: Class Pen. | Z1: Wear% | AA1: Raw Ovality% | AB1: Ovality% | AC1: Rem. F Wear | AD1: Rem. F. Ovality | AE1: Factor Ovality Total | AF1: Presion de Estallido API | AG1: Presion de Colapso API | AH1: Max | AI1: Presión de Estallido PSI | AJ1: Presión de Colapso PSI | AK1: Max. Ovality % | AL1: Max. Ovality Depth | AM1: Class Oval. | AO1: Min Wall MFC | AP1: Class Text | AQ1: XC1 | AR1: XC2 | AS1: 3D | AT1: LOG
A2: =Pozo -> Well-1 | B2: =campo -> Exploratorio | C2: =Pais -> Colombia | D2: =Departamento -> State | E2: =company -> Ecopetrol | F2: Expro | G2: =Logdate -> 24/5/2022 | H2: 7 | I2: 6.366 | J2: =(H2-I2)/2 -> 0.317 | K2: 1 | L2: 20.969 | M2: 37.693 | N2: 16.725 | O2: 6.3575001 | P2: 31.299999 | Q2: 0.33299995 | R2: 5.8070426 | S2: 23.9 | T2: 0.29977608 | U2: 6.4619999 | V2: 22.299999 | W2: 0.26900005 | X2: 15.141915 | Y2: =IF((1-AO2)<20%,"I",IF((1-AO2)<40%,"II",IF((1-AO2)<60%,"III",IF((1-AO2)<80%,"IV","V")))) -> I | Z2: =+((J2-W2)/J2)*100 -> 15.141939 | AA2: =+((U2/O2)-1)*100 -> 1.6437249 | AB2: =+(((U2-(T2-W2))/O2)-1)*100 -> 1.1596348 | AC2: =+(100-Z2)/100 -> 0.84858061 | AD2: =IF(AB2>=0.5,(1-(0.05*(AB2-0.5))),1) -> 0.96701826 | AE2: =ROUND(AC2*AD2,2) -> 0.82 | AF2: 6340 | AG2: 3830 | AH2: =AK2/100 -> 0.012806366 | AI2: =+AC2*AF2 -> 5380.0011 | AJ2: =+AE2*AG2 -> 3140.6 | AK2: 1.2806366 | AL2: 22.4 | AM2: =IF((AH2)<2%,"I",IF((AH2)<5%,"II","III")) -> I | AO2: =((100*W2)/J2)% -> 0.84858061 | AP2: =IF(Y2="I","Daño del 0-15%",IF(Y2="II","Daño del 15-25%",IF(Y2="III","Daño del 25-50%","Daño del 50-100%"))) -> Daño del 0-15% | AQ2: =Path&"images\sec_max_pen_T"&$K2&".png" -> D:\1. Pozos\11. Noviembre\4. DT-96\images\sec_max_pen_T1.png | AR2: =Path&"images\sec_max_res_T"&$K2&".png" -> D:\1. Pozos\11. Noviembre\4. DT-96\images\sec_max_res_T1.png | AS2: =Path&"images\"&$K2&".emf" -> D:\1. Pozos\11. Noviembre\4. DT-96\images\1.emf | AT2: =Path&"images\GraficaIntegradaT"&$K2&".png" -> D:\1. Pozos\11. Noviembre\4. DT-96\images\GraficaIntegradaT1.png
A3: =Pozo -> Well-1 | B3: =campo -> Exploratorio | C3: =Pais -> Colombia | D3: =Departamento -> State | E3: =company -> Ecopetrol | F3: Expro | G3: =Logdate -> 24/5/2022 | H3: 7 | I3: 6.366 | J3: =(H3-I3)/2 -> 0.317 | K3: 2 | L3: 40.079 | M3: 77.681 | N3: 37.603 | O3: 6.3515005 | P3: 47.700001 | Q3: 0.33450007 | R3: 12.746561 | S3: 77.699997 | T3: 0.30135012 | U3: 6.4660001 | V3: 77.699997 | W3: 0.26699996 | X3: 15.77286 | Y3: =IF((1-AO3)<20%,"I",IF((1-AO3)<40%,"II",IF((1-AO3)<60%,"III",IF((1-AO3)<80%,"IV","V")))) -> I | Z3: =+((J3-W3)/J3)*100 -> 15.772883 | AA3: =+((U3/O3)-1)*100 -> 1.8027169 | AB3: =+(((U3-(T3-W3))/O3)-1)*100 -> 1.2618973 | AC3: =+(100-Z3)/100 -> 0.84227117 | AD3: =IF(AB3>=0.5,(1-(0.05*(AB3-0.5))),1) -> 0.96190514 | AE3: =ROUND(AC3*AD3,2) -> 0.81 | AF3: 6340 | AG3: 3830 | AH3: =AK3/100 -> 0.011702285 | AI3: =+AC3*AF3 -> 5339.9992 | AJ3: =+AE3*AG3 -> 3102.3 | AK3: 1.1702285 | AL3: 59.599998 | AM3: =IF((AH3)<2%,"I",IF((AH3)<5%,"II","III")) -> I | AO3: =((100*W3)/J3)% -> 0.84227117 | AP3: =IF(Y3="I","Daño del 0-15%",IF(Y3="II","Daño del 15-25%",IF(Y3="III","Daño del 25-50%","Daño del 50-100%"))) -> Daño del 0-15% | AQ3: =Path&"images\sec_max_pen_T"&$K3&".png" -> D:\1. Pozos\11. Noviembre\4. DT-96\images\sec_max_pen_T2.png | AR3: =Path&"images\sec_max_res_T"&$K3&".png" -> D:\1. Pozos\11. Noviembre\4. DT-96\images\sec_max_res_T2.png | AS3: =Path&"images\"&$K3&".emf" -> D:\1. Pozos\11. Noviembre\4. DT-96\images\2.emf | AT3: =Path&"images\GraficaIntegradaT"&$K3&".png" -> D:\1. Pozos\11. Noviembre\4. DT-96\images\GraficaIntegradaT2.png
A4: =Pozo -> Well-1 | B4: =campo -> Exploratorio | C4: =Pais -> Colombia | D4: =Departamento -> State | E4: =company -> Ecopetrol | F4: Expro | G4: =Logdate -> 24/5/2022 | H4: 7 | I4: 6.366 | J4: =(H4-I4)/2 -> 0.317 | K4: 3 | L4: 79.181 | M4: 116.682 | N4: 37.5 | O4: 6.3425002 | P4: 79.199997 | Q4: 0.33850002 | R4: 9.0740309 | S4: 116.7 | T4: 0.30181646 | U4: 6.46 | V4: 102.3 | W4: 0.26999998 | X4: 14.826481 | Y4: =IF((1-AO4)<20%,"I",IF((1-AO4)<40%,"II",IF((1-AO4)<60%,"III",IF((1-AO4)<80%,"IV","V")))) -> I | Z4: =+((J4-W4)/J4)*100 -> 14.826504 | AA4: =+((U4/O4)-1)*100 -> 1.852579 | AB4: =+(((U4-(T4-W4))/O4)-1)*100 -> 1.3509396 | AC4: =+(100-Z4)/100 -> 0.85173496 | AD4: =IF(AB4>=0.5,(1-(0.05*(AB4-0.5))),1) -> 0.95745302 | AE4: =ROUND(AC4*AD4,2) -> 0.82 | AF4: 6340 | AG4: 3830 | AH4: =AK4/100 -> 0.013934943 | AI4: =+AC4*AF4 -> 5399.9996 | AJ4: =+AE4*AG4 -> 3140.6 | AK4: 1.3934943 | AL4: 97.599998 | AM4: =IF((AH4)<2%,"I",IF((AH4)<5%,"II","III")) -> I | AO4: =((100*W4)/J4)% -> 0.85173496 | AP4: =IF(Y4="I","Daño del 0-15%",IF(Y4="II","Daño del 15-25%",IF(Y4="III","Daño del 25-50%","Daño del 50-100%"))) -> Daño del 0-15% | AQ4: =Path&"images\sec_max_pen_T"&$K4&".png" -> D:\1. Pozos\11. Noviembre\4. DT-96\images\sec_max_pen_T3.png | AR4: =Path&"images\sec_max_res_T"&$K4&".png" -> D:\1. Pozos\11. Noviembre\4. DT-96\images\sec_max_res_T3.png | AS4: =Path&"images\"&$K4&".emf" -> D:\1. Pozos\11. Noviembre\4. DT-96\images\3.emf | AT4: =Path&"images\GraficaIntegradaT"&$K4&".png" -> D:\1. Pozos\11. Noviembre\4. DT-96\images\GraficaIntegradaT3.png
A5: =Pozo -> Well-1 | B5: =campo -> Exploratorio | C5: =Pais -> Colombia | D5: =Departamento -> State | E5: =company -> Ecopetrol | F5: Expro | G5: =Logdate -> 24/5/2022 | H5: 7 | I5: 6.366 | J5: =(H5-I5)/2 -> 0.317 | K5: 4 | L5: 118.182 | M5: 154.523 | N5: 36.342 | O5: 6.3360004 | P5: 126.2 | Q5: 0.34200001 | R5: 6.6908283 | S5: 154.3 | T5: 0.29940033 | U5: 6.4759998 | V5: 144.8 | W5: 0.26200008 | X5: 17.350109 | Y5: =IF((1-AO5)<20%,"I",IF((1-AO5)<40%,"II",IF((1-AO5)<60%,"III",IF((1-AO5)<80%,"IV","V")))) -> I | Z5: =+((J5-W5)/J5)*100 -> 17.350131 | AA5: =+((U5/O5)-1)*100 -> 2.2095862 | AB5: =+(((U5-(T5-W5))/O5)-1)*100 -> 1.6193046 | AC5: =+(100-Z5)/100 -> 0.82649869 | AD5: =IF(AB5>=0.5,(1-(0.05*(AB5-0.5))),1) -> 0.94403477 | AE5: =ROUND(AC5*AD5,2) -> 0.78 | AF5: 6340 | AG5: 3830 | AH5: =AK5/100 -> 0.01751743 | AI5: =+AC5*AF5 -> 5240.0017 | AJ5: =+AE5*AG5 -> 2987.4 | AK5: 1.751743 | AL5: 139.60001 | AM5: =IF((AH5)<2%,"I",IF((AH5)<5%,"II","III")) -> I | AO5: =((100*W5)/J5)% -> 0.82649869 | AP5: =IF(Y5="I","Daño del 0-15%",IF(Y5="II","Daño del 15-25%",IF(Y5="III","Daño del 25-50%","Daño del 50-100%"))) -> Daño del 0-15% | AQ5: =Path&"images\sec_max_pen_T"&$K5&".png" -> D:\1. Pozos\11. Noviembre\4. DT-96\images\sec_max_pen_T4.png | AR5: =Path&"images\sec_max_res_T"&$K5&".png" -> D:\1. Pozos\11. Noviembre\4. DT-96\images\sec_max_res_T4.png | AS5: =Path&"images\"&$K5&".emf" -> D:\1. Pozos\11. Noviembre\4. DT-96\images\4.emf | AT5: =Path&"images\GraficaIntegradaT"&$K5&".png" -> D:\1. Pozos\11. Noviembre\4. DT-96\images\GraficaIntegradaT4.png
A6: =Pozo -> Well-1 | B6: =campo -> Exploratorio | C6: =Pais -> Colombia | D6: =Departamento -> State | E6: =company -> Ecopetrol | F6: Expro | G6: =Logdate -> 24/5/2022 | H6: 7 | I6: 6.366 | J6: =(H6-I6)/2 -> 0.317 | K6: 5 | L6: 156.023 | M6: 194.103 | N6: 38.08 | O6: 6.3555002 | P6: 191.39999 | Q6: 0.33249998 | R6: 6.9302497 | S6: 158.5 | T6: 0.29968381 | U6: 6.4640002 | V6: 170.8 | W6: 0.26799989 | X6: 15.457425 | Y6: =IF((1-AO6)<20%,"I",IF((1-AO6)<40%,"II",IF((1-AO6)<60%,"III",IF((1-AO6)<80%,"IV","V")))) -> I | Z6: =+((J6-W6)/J6)*100 -> 15.457449 | AA6: =+((U6/O6)-1)*100 -> 1.7071829 | AB6: =+(((U6-(T6-W6))/O6)-1)*100 -> 1.2086553 | AC6: =+(100-Z6)/100 -> 0.84542551 | AD6: =IF(AB6>=0.5,(1-(0.05*(AB6-0.5))),1) -> 0.96456724 | AE6: =ROUND(AC6*AD6,2) -> 0.82 | AF6: 6340 | AG6: 3830 | AH6: =AK6/100 -> 0.012017173 | AI6: =+AC6*AF6 -> 5359.9977 | AJ6: =+AE6*AG6 -> 3140.6 | AK6: 1.2017173 | AL6: 172.2 | AM6: =IF((AH6)<2%,"I",IF((AH6)<5%,"II","III")) -> I | AO6: =((100*W6)/J6)% -> 0.84542551 | AP6: =IF(Y6="I","Daño del 0-15%",IF(Y6="II","Daño del 15-25%",IF(Y6="III","Daño del 25-50%","Daño del 50-100%"))) -> Daño del 0-15% | AQ6: =Path&"images\sec_max_pen_T"&$K6&".png" -> D:\1. Pozos\11. Noviembre\4. DT-96\images\sec_max_pen_T5.png | AR6: =Path&"images\sec_max_res_T"&$K6&".png" -> D:\1. Pozos\11. Noviembre\4. DT-96\images\sec_max_res_T5.png | AS6: =Path&"images\"&$K6&".emf" -> D:\1. Pozos\11. Noviembre\4. DT-96\images\5.emf | AT6: =Path&"images\GraficaIntegradaT"&$K6&".png" -> D:\1. Pozos\11. Noviembre\4. DT-96\images\GraficaIntegradaT5.png
A7: =Pozo -> Well-1 | B7: =campo -> Exploratorio | C7: =Pais -> Colombia | D7: =Departamento -> State | E7: =company -> Ecopetrol | F7: Expro | G7: =Logdate -> 24/5/2022 | H7: 7 | I7: 6.366 | J7: =(H7-I7)/2 -> 0.317 | K7: 6 | L7: 195.603 | M7: 231.173 | N7: 35.57 | O7: 6.3330002 | P7: 203.60001 | Q7: 0.3434999 | R7: 6.9557118 | S7: 215.60001 | T7: 0.29740286 | U7: 6.4840002 | V7: 203.5 | W7: 0.2579999 | X7: 18.611998 | Y7: =IF((1-AO7)<20%,"I",IF((1-AO7)<40%,"II",IF((1-AO7)<60%,"III",IF((1-AO7)<80%,"IV","V")))) -> I | Z7: =+((J7-W7)/J7)*100 -> 18.61202 | AA7: =+((U7/O7)-1)*100 -> 2.3843364 | AB7: =+(((U7-(T7-W7))/O7)-1)*100 -> 1.7621517 | AC7: =+(100-Z7)/100 -> 0.8138798 | AD7: =IF(AB7>=0.5,(1-(0.05*(AB7-0.5))),1) -> 0.93689242 | AE7: =ROUND(AC7*AD7,2) -> 0.76 | AF7: 6340 | AG7: 3830 | AH7: =AK7/100 -> 0.018342278 | AI7: =+AC7*AF7 -> 5159.9979 | AJ7: =+AE7*AG7 -> 2910.8 | AK7: 1.8342278 | AL7: 203.5 | AM7: =IF((AH7)<2%,"I",IF((AH7)<5%,"II","III")) -> I | AO7: =((100*W7)/J7)% -> 0.8138798 | AP7: =IF(Y7="I","Daño del 0-15%",IF(Y7="II","Daño del 15-25%",IF(Y7="III","Daño del 25-50%","Daño del 50-100%"))) -> Daño del 0-15% | AQ7: =Path&"images\sec_max_pen_T"&$K7&".png" -> D:\1. Pozos\11. Noviembre\4. DT-96\images\sec_max_pen_T6.png | AR7: =Path&"images\sec_max_res_T"&$K7&".png" -> D:\1. Pozos\11. Noviembre\4. DT-96\images\sec_max_res_T6.png | AS7: =Path&"images\"&$K7&".emf" -> D:\1. Pozos\11. Noviembre\4. DT-96\images\6.emf | AT7: =Path&"images\GraficaIntegradaT"&$K7&".png" -> D:\1. Pozos\11. Noviembre\4. DT-96\images\GraficaIntegradaT6.png
A8: =Pozo -> Well-1 | B8: =campo -> Exploratorio | C8: =Pais -> Colombia | D8: =Departamento -> State | E8: =company -> Ecopetrol | F8: Expro | G8: =Logdate -> 24/5/2022 | H8: 7 | I8: 6.366 | J8: =(H8-I8)/2 -> 0.317 | K8: 7 | L8: 232.673 | M8: 272.104 | N8: 39.431 | O8: 6.3380003 | P8: 256.39999 | Q8: 0.33899999 | R8: 8.0421581 | S8: 232.7 | T8: 0.2991159 | U8: 6.474 | V8: 249.60001 | W8: 0.26300001 | X8: 17.034674 | Y8: =IF((1-AO8)<20%,"I",IF((1-AO8)<40%,"II",IF((1-AO8)<60%,"III",IF((1-AO8)<80%,"IV","V")))) -> I | Z8: =+((J8-W8)/J8)*100 -> 17.034697 | AA8: =+((U8/O8)-1)*100 -> 2.1457822 | AB8: =+(((U8-(T8-W8))/O8)-1)*100 -> 1.5759513 | AC8: =+(100-Z8)/100 -> 0.82965303 | AD8: =IF(AB8>=0.5,(1-(0.05*(AB8-0.5))),1) -> 0.94620244 | AE8: =ROUND(AC8*AD8,2) -> 0.79 | AF8: 6340 | AG8: 3830 | AH8: =AK8/100 -> 0.01721499 | AI8: =+AC8*AF8 -> 5260.0002 | AJ8: =+AE8*AG8 -> 3025.7 | AK8: 1.721499 | AL8: 249.8 | AM8: =IF((AH8)<2%,"I",IF((AH8)<5%,"II","III")) -> I | AO8: =((100*W8)/J8)% -> 0.82965303 | AP8: =IF(Y8="I","Daño del 0-15%",IF(Y8="II","Daño del 15-25%",IF(Y8="III","Daño del 25-50%","Daño del 50-100%"))) -> Daño del 0-15% | AQ8: =Path&"images\sec_max_pen_T"&$K8&".png" -> D:\1. Pozos\11. Noviembre\4. DT-96\images\sec_max_pen_T7.png | AR8: =Path&"images\sec_max_res_T"&$K8&".png" -> D:\1. Pozos\11. Noviembre\4. DT-96\images\sec_max_res_T7.png | AS8: =Path&"images\"&$K8&".emf" -> D:\1. Pozos\11. Noviembre\4. DT-96\images\7.emf | AT8: =Path&"images\GraficaIntegradaT"&$K8&".png" -> D:\1. Pozos\11. Noviembre\4. DT-96\images\GraficaIntegradaT7.png
A9: =Pozo -> Well-1 | B9: =campo -> Exploratorio | C9: =Pais -> Colombia | D9: =Departamento -> State | E9: =company -> Ecopetrol | F9: Expro | G9: =Logdate -> 24/5/2022 | H9: 7 | I9: 6.366 | J9: =(H9-I9)/2 -> 0.317 | K9: 8 | L9: 273.604 | M9: 313.228 | N9: 39.624 | O9: 6.3445001 | P9: 304 | Q9: 0.33649993 | R9: 7.5551505 | S9: 275.20001 | T9: 0.29765224 | U9: 6.4699998 | V9: 306.70001 | W9: 0.2650001 | X9: 16.403728 | Y9: =IF((1-AO9)<20%,"I",IF((1-AO9)<40%,"II",IF((1-AO9)<60%,"III",IF((1-AO9)<80%,"IV","V")))) -> I | Z9: =+((J9-W9)/J9)*100 -> 16.403752 | AA9: =+((U9/O9)-1)*100 -> 1.978087 | AB9: =+(((U9-(T9-W9))/O9)-1)*100 -> 1.4634343 | AC9: =+(100-Z9)/100 -> 0.83596248 | AD9: =IF(AB9>=0.5,(1-(0.05*(AB9-0.5))),1) -> 0.95182829 | AE9: =ROUND(AC9*AD9,2) -> 0.8 | AF9: 6340 | AG9: 3830 | AH9: =AK9/100 -> 0.015894539 | AI9: =+AC9*AF9 -> 5300.0021 | AJ9: =+AE9*AG9 -> 3064 | AK9: 1.5894539 | AL9: 304 | AM9: =IF((AH9)<2%,"I",IF((AH9)<5%,"II","III")) -> I | AO9: =((100*W9)/J9)% -> 0.83596248 | AP9: =IF(Y9="I","Daño del 0-15%",IF(Y9="II","Daño del 15-25%",IF(Y9="III","Daño del 25-50%","Daño del 50-100%"))) -> Daño del 0-15% | AQ9: =Path&"images\sec_max_pen_T"&$K9&".png" -> D:\1. Pozos\11. Noviembre\4. DT-96\images\sec_max_pen_T8.png | AR9: =Path&"images\sec_max_res_T"&$K9&".png" -> D:\1. Pozos\11. Noviembre\4. DT-96\images\sec_max_res_T8.png | AS9: =Path&"images\"&$K9&".emf" -> D:\1. Pozos\11. Noviembre\4. DT-96\images\8.emf | AT9: =Path&"images\GraficaIntegradaT"&$K9&".png" -> D:\1. Pozos\11. Noviembre\4. DT-96\images\GraficaIntegradaT8.png
A10: =Pozo -> Well-1 | B10: =campo -> Exploratorio | C10: =Pais -> Colombia | D10: =Departamento -> State | E10: =company -> Ecopetrol | F10: Expro | G10: =Logdate -> 24/5/2022 | H10: 7 | I10: 6.366 | J10: =(H10-I10)/2 -> 0.317 | K10: 9 | L10: 314.728 | M10: 353.773 | N10: 39.045 | O10: 6.3400001 | P10: 315 | Q10: 0.33450007 | R10: 8.8511543 | S10: 353.79999 | T10: 0.30120063 | U10: 6.4590001 | V10: 317.20001 | W10: 0.27049995 | X10: 14.668763 | Y10: =IF((1-AO10)<20%,"I",IF((1-AO10)<40%,"II",IF((1-AO10)<60%,"III",IF((1-AO10)<80%,"IV","V")))) -> I | Z10: =+((J10-W10)/J10)*100 -> 14.668787 | AA10: =+((U10/O10)-1)*100 -> 1.8769709 | AB10: =+(((U10-(T10-W10))/O10)-1)*100 -> 1.392733 | AC10: =+(100-Z10)/100 -> 0.85331213 | AD10: =IF(AB10>=0.5,(1-(0.05*(AB10-0.5))),1) -> 0.95536335 | AE10: =ROUND(AC10*AD10,2) -> 0.82 | AF10: 6340 | AG10: 3830 | AH10: =AK10/100 -> 0.013646386 | AI10: =+AC10*AF10 -> 5409.9989 | AJ10: =+AE10*AG10 -> 3140.6 | AK10: 1.3646386 | AL10: 314.89999 | AM10: =IF((AH10)<2%,"I",IF((AH10)<5%,"II","III")) -> I | AO10: =((100*W10)/J10)% -> 0.85331213 | AP10: =IF(Y10="I","Daño del 0-15%",IF(Y10="II","Daño del 15-25%",IF(Y10="III","Daño del 25-50%","Daño del 50-100%"))) -> Daño del 0-15% | AQ10: =Path&"images\sec_max_pen_T"&$K10&".png" -> D:\1. Pozos\11. Noviembre\4. DT-96\images\sec_max_pen_T9.png | AR10: =Path&"images\sec_max_res_T"&$K10&".png" -> D:\1. Pozos\11. Noviembre\4. DT-96\images\sec_max_res_T9.png | AS10: =Path&"images\"&$K10&".emf" -> D:\1. Pozos\11. Noviembre\4. DT-96\images\9.emf | AT10: =Path&"images\GraficaIntegradaT"&$K10&".png" -> D:\1. Pozos\11. Noviembre\4. DT-96\images\GraficaIntegradaT9.png
A11: =Pozo -> Well-1 | B11: =campo -> Exploratorio | C11: =Pais -> Colombia | D11: =Departamento -> State | E11: =company -> Ecopetrol | F11: Expro | G11: =Logdate -> 24/5/2022 | H11: 7 | I11: 6.366 | J11: =(H11-I11)/2 -> 0.317 | K11: 10 | L11: 355.273 | M11: 388.139 | N11: 32.867 | O11: 6.3345003 | P11: 378.10001 | Q11: 0.33800006 | R11: 4.6959901 | S11: 362.60001 | T11: 0.30508924 | U11: 6.4450002 | V11: 375.79999 | W11: 0.27749991 | X11: 12.46057 | Y11: =IF((1-AO11)<20%,"I",IF((1-AO11)<40%,"II",IF((1-AO11)<60%,"III",IF((1-AO11)<80%,"IV","V")))) -> I | Z11: =+((J11-W11)/J11)*100 -> 12.460595 | AA11: =+((U11/O11)-1)*100 -> 1.7444132 | AB11: =+(((U11-(T11-W11))/O11)-1)*100 -> 1.3088726 | AC11: =+(100-Z11)/100 -> 0.87539405 | AD11: =IF(AB11>=0.5,(1-(0.05*(AB11-0.5))),1) -> 0.95955637 | AE11: =ROUND(AC11*AD11,2) -> 0.84 | AF11: 6340 | AG11: 3830 | AH11: =AK11/100 -> 0.012404698 | AI11: =+AC11*AF11 -> 5549.9983 | AJ11: =+AE11*AG11 -> 3217.2 | AK11: 1.2404698 | AL11: 359.70001 | AM11: =IF((AH11)<2%,"I",IF((AH11)<5%,"II","III")) -> I | AO11: =((100*W11)/J11)% -> 0.87539405 | AP11: =IF(Y11="I","Daño del 0-15%",IF(Y11="II","Daño del 15-25%",IF(Y11="III","Daño del 25-50%","Daño del 50-100%"))) -> Daño del 0-15% | AQ11: =Path&"images\sec_max_pen_T"&$K11&".png" -> D:\1. Pozos\11. Noviembre\4. DT-96\images\sec_max_pen_T10.png | AR11: =Path&"images\sec_max_res_T"&$K11&".png" -> D:\1. Pozos\11. Noviembre\4. DT-96\images\sec_max_res_T10.png | AS11: =Path&"images\"&$K11&".emf" -> D:\1. Pozos\11. Noviembre\4. DT-96\images\10.emf | AT11: =Path&"images\GraficaIntegradaT"&$K11&".png" -> D:\1. Pozos\11. Noviembre\4. DT-96\images\GraficaIntegradaT10.png
A12: =Pozo -> Well-1 | B12: =campo -> Exploratorio | C12: =Pais -> Colombia | D12: =Departamento -> State | E12: =company -> Ecopetrol | F12: Expro | G12: =Logdate -> 24/5/2022 | H12: 7 | I12: 6.366 | J12: =(H12-I12)/2 -> 0.317 | K12: 11 | L12: 389.639 | M12: 428.105 | N12: 38.466 | O12: 6.3475003 | P12: 389.60001 | Q12: 0.3355 | R12: 12.518228 | S12: 428.10001 | T12: 0.30185652 | U12: 6.4759998 | V12: 428.10001 | W12: 0.26200008 | X12: 17.350109 | Y12: =IF((1-AO12)<20%,"I",IF((1-AO12)<40%,"II",IF((1-AO12)<60%,"III",IF((1-AO12)<80%,"IV","V")))) -> I | Z12: =+((J12-W12)/J12)*100 -> 17.350131 | AA12: =+((U12/O12)-1)*100 -> 2.0244112 | AB12: =+(((U12-(T12-W12))/O12)-1)*100 -> 1.3965037 | AC12: =+(100-Z12)/100 -> 0.82649869 | AD12: =IF(AB12>=0.5,(1-(0.05*(AB12-0.5))),1) -> 0.95517482 | AE12: =ROUND(AC12*AD12,2) -> 0.79 | AF12: 6340 | AG12: 3830 | AH12: =AK12/100 -> 0.016394076 | AI12: =+AC12*AF12 -> 5240.0017 | AJ12: =+AE12*AG12 -> 3025.7 | AK12: 1.6394076 | AL12: 389.60001 | AM12: =IF((AH12)<2%,"I",IF((AH12)<5%,"II","III")) -> I | AO12: =((100*W12)/J12)% -> 0.82649869 | AP12: =IF(Y12="I","Daño del 0-15%",IF(Y12="II","Daño del 15-25%",IF(Y12="III","Daño del 25-50%","Daño del 50-100%"))) -> Daño del 0-15% | AQ12: =Path&"images\sec_max_pen_T"&$K12&".png" -> D:\1. Pozos\11. Noviembre\4. DT-96\images\sec_max_pen_T11.png | AR12: =Path&"images\sec_max_res_T"&$K12&".png" -> D:\1. Pozos\11. Noviembre\4. DT-96\images\sec_max_res_T11.png | AS12: =Path&"images\"&$K12&".emf" -> D:\1. Pozos\11. Noviembre\4. DT-96\images\11.emf | AT12: =Path&"images\GraficaIntegradaT"&$K12&".png" -> D:\1. Pozos\11. Noviembre\4. DT-96\images\GraficaIntegradaT11.png
A13: =Pozo -> Well-1 | B13: =campo -> Exploratorio | C13: =Pais -> Colombia | D13: =Departamento -> State | E13: =company -> Ecopetrol | F13: Expro | G13: =Logdate -> 24/5/2022 | H13: 7 | I13: 6.366 | J13: =(H13-I13)/2 -> 0.317 | K13: 12 | L13: 429.605 | M13: 468.457 | N13: 38.852 | O13: 6.3535004 | P13: 429.60001 | Q13: 0.33299995 | R13: 12.746413 | S13: 468.5 | T13: 0.29850793 | U13: 6.4759998 | V13: 442.39999 | W13: 0.26200008 | X13: 17.350109 | Y13: =IF((1-AO13)<20%,"I",IF((1-AO13)<40%,"II",IF((1-AO13)<60%,"III",IF((1-AO13)<80%,"IV","V")))) -> I | Z13: =+((J13-W13)/J13)*100 -> 17.350131 | AA13: =+((U13/O13)-1)*100 -> 1.9280625 | AB13: =+(((U13-(T13-W13))/O13)-1)*100 -> 1.3534526 | AC13: =+(100-Z13)/100 -> 0.82649869 | AD13: =IF(AB13>=0.5,(1-(0.05*(AB13-0.5))),1) -> 0.95732737 | AE13: =ROUND(AC13*AD13,2) -> 0.79 | AF13: 6340 | AG13: 3830 | AH13: =AK13/100 -> 0.014711544 | AI13: =+AC13*AF13 -> 5240.0017 | AJ13: =+AE13*AG13 -> 3025.7 | AK13: 1.4711545 | AL13: 429.79999 | AM13: =IF((AH13)<2%,"I",IF((AH13)<5%,"II","III")) -> I | AO13: =((100*W13)/J13)% -> 0.82649869 | AP13: =IF(Y13="I","Daño del 0-15%",IF(Y13="II","Daño del 15-25%",IF(Y13="III","Daño del 25-50%","Daño del 50-100%"))) -> Daño del 0-15% | AQ13: =Path&"images\sec_max_pen_T"&$K13&".png" -> D:\1. Pozos\11. Noviembre\4. DT-96\images\sec_max_pen_T12.png | AR13: =Path&"images\sec_max_res_T"&$K13&".png" -> D:\1. Pozos\11. Noviembre\4. DT-96\images\sec_max_res_T12.png | AS13: =Path&"images\"&$K13&".emf" -> D:\1. Pozos\11. Noviembre\4. DT-96\images\12.emf | AT13: =Path&"images\GraficaIntegradaT"&$K13&".png" -> D:\1. Pozos\11. Noviembre\4. DT-96\images\GraficaIntegradaT12.png
... A46: =Pozo -> Well-1 | B46: =campo -> Exploratorio | C46: =Pais -> Colombia | D46: =Departamento -> State | E46: =company -> Ecopetrol | F46: Expro | G46: =Logdate -> 24/5/2022 | H46: 7 | I46: 6.366 | J46: =(H46-I46)/2 -> 0.317 | K46: 45 | L46: 1741.136 | M46: 1781.726 | N46: 40.589 | O46: 6.2410002 | P46: 1776.6999 | Q46: 0.38199997 | R46: 8.7148495 | S46: 1776.6 | T46: 0.30323696 | U46: 6.5479999 | V46: 1776.6999 | W46: 0.22600007 | X46: 28.706583 | Y46: =IF((1-AO46)<20%,"I",IF((1-AO46)<40%,"II",IF((1-AO46)<60%,"III",IF((1-AO46)<80%,"IV","V")))) -> II | Z46: =+((J46-W46)/J46)*100 -> 28.706602 | AA46: =+((U46/O46)-1)*100 -> 4.9190782 | AB46: =+(((U46-(T46-W46))/O46)-1)*100 -> 3.6815059 | AC46: =+(100-Z46)/100 -> 0.71293398 | AD46: =IF(AB46>=0.5,(1-(0.05*(AB46-0.5))),1) -> 0.8409247 | AE46: =ROUND(AC46*AD46,2) -> 0.6 | AF46: 6340 | AG46: 3830 | AH46: =AK46/100 -> 0.045601993 | AI46: =+AC46*AF46 -> 4520.0014 | AJ46: =+AE46*AG46 -> 2298 | AK46: 4.5601993 | AL46: 1776.6999 | AM46: =IF((AH46)<2%,"I",IF((AH46)<5%,"II","III")) -> II | AO46: =((100*W46)/J46)% -> 0.71293398 | AP46: =IF(Y46="I","Daño del 0-15%",IF(Y46="II","Daño del 15-25%",IF(Y46="III","Daño del 25-50%","Daño del 50-100%"))) -> Daño del 15-25% | AQ46: =Path&"images\sec_max_pen_T"&$K46&".png" -> D:\1. Pozos\11. Noviembre\4. DT-96\images\sec_max_pen_T45.png | AR46: =Path&"images\sec_max_res_T"&$K46&".png" -> D:\1. Pozos\11. Noviembre\4. DT-96\images\sec_max_res_T45.png | AS46: =Path&"images\"&$K46&".emf" -> D:\1. Pozos\11. Noviembre\4. DT-96\images\45.emf | AT46: =Path&"images\GraficaIntegradaT"&$K46&".png" -> D:\1. Pozos\11. Noviembre\4. DT-96\images\GraficaIntegradaT45.png
A47: =Pozo -> Well-1 | C47: =Pais -> Colombia | D47: =Departamento -> State | E47: =company -> Ecopetrol | F47: Expro | G47: =Logdate -> 24/5/2022 | H47: 7 | I47: 6.366 | J47: =(H47-I47)/2 -> 0.317 | K47: 46 | L47: 1783.226 | M47: 1823.236 | N47: 40.01 | O47: 6.2255001 | P47: 1802.1 | Q47: 0.4460001 | R47: 12.146178 | S47: 1823.1999 | T47: 0.30734038 | U47: 6.473 | V47: 1790.1999 | W47: 0.26349997 | X47: 16.876957 | Y47: =IF((1-AO47)<20%,"I",IF((1-AO47)<40%,"II",IF((1-AO47)<60%,"III",IF((1-AO47)<80%,"IV","V")))) -> I | Z47: =+((J47-W47)/J47)*100 -> 16.876979 | AA47: =+((U47/O47)-1)*100 -> 3.9755833 | AB47: =+(((U47-(T47-W47))/O47)-1)*100 -> 3.2713762 | AC47: =+(100-Z47)/100 -> 0.83123021 | AD47: =IF(AB47>=0.5,(1-(0.05*(AB47-0.5))),1) -> 0.86143119 | AE47: =ROUND(AC47*AD47,2) -> 0.72 | AF47: 6340 | AG47: 3830 | AH47: =AK47/100 -> 0.017500088 | AI47: =+AC47*AF47 -> 5269.9995 | AJ47: =+AE47*AG47 -> 2757.6 | AK47: 1.7500088 | AL47: 1789.8001 | AM47: =IF((AH47)<2%,"I",IF((AH47)<5%,"II","III")) -> I | AO47: =((100*W47)/J47)% -> 0.83123021 | AP47: =IF(Y47="I","Daño del 0-15%",IF(Y47="II","Daño del 15-25%",IF(Y47="III","Daño del 25-50%","Daño del 50-100%"))) -> Daño del 0-15% | AQ47: =Path&"images\sec_max_pen_T"&$K47&".png" -> D:\1. Pozos\11. Noviembre\4. DT-96\images\sec_max_pen_T46.png | AR47: =Path&"images\sec_max_res_T"&$K47&".png" -> D:\1. Pozos\11. Noviembre\4. DT-96\images\sec_max_res_T46.png | AS47: =Path&"images\"&$K47&".emf" -> D:\1. Pozos\11. Noviembre\4. DT-96\images\46.emf | AT47: =Path&"images\GraficaIntegradaT"&$K47&".png" -> D:\1. Pozos\11. Noviembre\4. DT-96\images\GraficaIntegradaT46.png
A48: =Pozo -> Well-1 | B48: =campo -> Exploratorio | C48: =Pais -> Colombia | D48: =Departamento -> State | E48: =company -> Ecopetrol | F48: Expro | G48: =Logdate -> 24/5/2022 | H48: 7 | I48: 6.366 | J48: =(H48-I48)/2 -> 0.317 | K48: 47 | L48: 1824.736 | M48: 1863.974 | N48: 39.238 | O48: 6.3275003 | P48: 1840.3001 | Q48: 0.34249997 | R48: 6.1151028 | S48: 1863.5 | T48: 0.30138111 | U48: 6.4860001 | V48: 1863.6999 | W48: 0.25699997 | X48: 18.927431 | Y48: =IF((1-AO48)<20%,"I",IF((1-AO48)<40%,"II",IF((1-AO48)<60%,"III",IF((1-AO48)<80%,"IV","V")))) -> I | Z48: =+((J48-W48)/J48)*100 -> 18.927455 | AA48: =+((U48/O48)-1)*100 -> 2.5049342 | AB48: =+(((U48-(T48-W48))/O48)-1)*100 -> 1.8035333 | AC48: =+(100-Z48)/100 -> 0.81072545 | AD48: =IF(AB48>=0.5,(1-(0.05*(AB48-0.5))),1) -> 0.93482333 | AE48: =ROUND(AC48*AD48,2) -> 0.76 | AF48: 6340 | AG48: 3830 | AH48: =AK48/100 -> 0.020087757 | AI48: =+AC48*AF48 -> 5139.9994 | AJ48: =+AE48*AG48 -> 2910.8 | AK48: 2.0087757 | AL48: 1863.4 | AM48: =IF((AH48)<2%,"I",IF((AH48)<5%,"II","III")) -> II | AO48: =((100*W48)/J48)% -> 0.81072545 | AP48: =IF(Y48="I","Daño del 0-15%",IF(Y48="II","Daño del 15-25%",IF(Y48="III","Daño del 25-50%","Daño del 50-100%"))) -> Daño del 0-15% | AQ48: =Path&"images\sec_max_pen_T"&$K48&".png" -> D:\1. Pozos\11. Noviembre\4. DT-96\images\sec_max_pen_T47.png | AR48: =Path&"images\sec_max_res_T"&$K48&".png" -> D:\1. Pozos\11. Noviembre\4. DT-96\images\sec_max_res_T47.png | AS48: =Path&"images\"&$K48&".emf" -> D:\1. Pozos\11. Noviembre\4. DT-96\images\47.emf | AT48: =Path&"images\GraficaIntegradaT"&$K48&".png" -> D:\1. Pozos\11. Noviembre\4. DT-96\images\GraficaIntegradaT47.png
A49: =Pozo -> Well-1 | B49: =campo -> Exploratorio | C49: =Pais -> Colombia | D49: =Departamento -> State | E49: =company -> Ecopetrol | F49: Expro | G49: =Logdate -> 24/5/2022 | H49: 7 | I49: 6.366 | J49: =(H49-I49)/2 -> 0.317 | K49: 48 | L49: 1865.474 | M49: 1906.45 | N49: 40.976 | O49: 6.2525005 | P49: 1869.5 | Q49: 0.37849998 | R49: 12.822715 | S49: 1906.4 | T49: 0.3016541 | U49: 6.5380001 | V49: 1869.3001 | W49: 0.23099995 | X49: 27.129334 | Y49: =IF((1-AO49)<20%,"I",IF((1-AO49)<40%,"II",IF((1-AO49)<60%,"III",IF((1-AO49)<80%,"IV","V")))) -> II | Z49: =+((J49-W49)/J49)*100 -> 27.129354 | AA49: =+((U49/O49)-1)*100 -> 4.5661664 | AB49: =+(((U49-(T49-W49))/O49)-1)*100 -> 3.4361521 | AC49: =+(100-Z49)/100 -> 0.72870646 | AD49: =IF(AB49>=0.5,(1-(0.05*(AB49-0.5))),1) -> 0.8531924 | AE49: =ROUND(AC49*AD49,2) -> 0.62 | AF49: 6340 | AG49: 3830 | AH49: =AK49/100 -> 0.043377147 | AI49: =+AC49*AF49 -> 4619.9989 | AJ49: =+AE49*AG49 -> 2374.6 | AK49: 4.3377147 | AL49: 1869.3001 | AM49: =IF((AH49)<2%,"I",IF((AH49)<5%,"II","III")) -> II | AO49: =((100*W49)/J49)% -> 0.72870646 | AP49: =IF(Y49="I","Daño del 0-15%",IF(Y49="II","Daño del 15-25%",IF(Y49="III","Daño del 25-50%","Daño del 50-100%"))) -> Daño del 15-25% | AQ49: =Path&"images\sec_max_pen_T"&$K49&".png" -> D:\1. Pozos\11. Noviembre\4. DT-96\images\sec_max_pen_T48.png | AR49: =Path&"images\sec_max_res_T"&$K49&".png" -> D:\1. Pozos\11. Noviembre\4. DT-96\images\sec_max_res_T48.png | AS49: =Path&"images\"&$K49&".emf" -> D:\1. Pozos\11. Noviembre\4. DT-96\images\48.emf | AT49: =Path&"images\GraficaIntegradaT"&$K49&".png" -> D:\1. Pozos\11. Noviembre\4. DT-96\images\GraficaIntegradaT48.png
A50: =Pozo -> Well-1 | B50: =campo -> Exploratorio | C50: =Pais -> Colombia | D50: =Departamento -> State | E50: =company -> Ecopetrol | F50: Expro | G50: =Logdate -> 24/5/2022 | H50: 7 | I50: 6.366 | J50: =(H50-I50)/2 -> 0.317 | K50: 49 | L50: 1907.95 | M50: 1946.994 | N50: 39.045 | O50: 6.3250003 | P50: 1914.1999 | Q50: 0.34549999 | R50: 6.1865583 | S50: 1943.1999 | T50: 0.30040717 | U50: 6.487 | V50: 1908.1 | W50: 0.25650001 | X50: 19.08515 | Y50: =IF((1-AO50)<20%,"I",IF((1-AO50)<40%,"II",IF((1-AO50)<60%,"III",IF((1-AO50)<80%,"IV","V")))) -> I | Z50: =+((J50-W50)/J50)*100 -> 19.085172 | AA50: =+((U50/O50)-1)*100 -> 2.56126 | AB50: =+(((U50-(T50-W50))/O50)-1)*100 -> 1.8670756 | AC50: =+(100-Z50)/100 -> 0.80914828 | AD50: =IF(AB50>=0.5,(1-(0.05*(AB50-0.5))),1) -> 0.93164622 | AE50: =ROUND(AC50*AD50,2) -> 0.75 | AF50: 6340 | AG50: 3830 | AH50: =AK50/100 -> 0.021731055 | AI50: =+AC50*AF50 -> 5130.0001 | AJ50: =+AE50*AG50 -> 2872.5 | AK50: 2.1731055 | AL50: 1913.6 | AM50: =IF((AH50)<2%,"I",IF((AH50)<5%,"II","III")) -> II | AO50: =((100*W50)/J50)% -> 0.80914828 | AP50: =IF(Y50="I","Daño del 0-15%",IF(Y50="II","Daño del 15-25%",IF(Y50="III","Daño del 25-50%","Daño del 50-100%"))) -> Daño del 0-15% | AQ50: =Path&"images\sec_max_pen_T"&$K50&".png" -> D:\1. Pozos\11. Noviembre\4. DT-96\images\sec_max_pen_T49.png | AR50: =Path&"images\sec_max_res_T"&$K50&".png" -> D:\1. Pozos\11. Noviembre\4. DT-96\images\sec_max_res_T49.png | AS50: =Path&"images\"&$K50&".emf" -> D:\1. Pozos\11. Noviembre\4. DT-96\images\49.emf | AT50: =Path&"images\GraficaIntegradaT"&$K50&".png" -> D:\1. Pozos\11. Noviembre\4. DT-96\images\GraficaIntegradaT49.png
A51: =Pozo -> Well-1 | B51: =campo -> Exploratorio | C51: =Pais -> Colombia | D51: =Departamento -> State | E51: =company -> Ecopetrol | F51: Expro | G51: =Logdate -> 24/5/2022 | H51: 7 | I51: 6.366 | J51: =(H51-I51)/2 -> 0.317 | K51: 50 | L51: 1948.494 | M51: 1988.312 | N51: 39.817 | O51: 6.2975001 | P51: 1962.6 | Q51: 0.36249995 | R51: 7.3358617 | S51: 1964.6999 | T51: 0.30226159 | U51: 6.5159998 | V51: 1964.4 | W51: 0.2420001 | X51: 23.659252 | Y51: =IF((1-AO51)<20%,"I",IF((1-AO51)<40%,"II",IF((1-AO51)<60%,"III",IF((1-AO51)<80%,"IV","V")))) -> II | Z51: =+((J51-W51)/J51)*100 -> 23.659274 | AA51: =+((U51/O51)-1)*100 -> 3.4696253 | AB51: =+(((U51-(T51-W51))/O51)-1)*100 -> 2.5127141 | AC51: =+(100-Z51)/100 -> 0.76340726 | AD51: =IF(AB51>=0.5,(1-(0.05*(AB51-0.5))),1) -> 0.8993643 | AE51: =ROUND(AC51*AD51,2) -> 0.69 | AF51: 6340 | AG51: 3830 | AH51: =AK51/100 -> 0.030612154 | AI51: =+AC51*AF51 -> 4840.0021 | AJ51: =+AE51*AG51 -> 2642.7 | AK51: 3.0612154 | AL51: 1964.6999 | AM51: =IF((AH51)<2%,"I",IF((AH51)<5%,"II","III")) -> II | AO51: =((100*W51)/J51)% -> 0.76340726 | AP51: =IF(Y51="I","Daño del 0-15%",IF(Y51="II","Daño del 15-25%",IF(Y51="III","Daño del 25-50%","Daño del 50-100%"))) -> Daño del 15-25% | AQ51: =Path&"images\sec_max_pen_T"&$K51&".png" -> D:\1. Pozos\11. Noviembre\4. DT-96\images\sec_max_pen_T50.png | AR51: =Path&"images\sec_max_res_T"&$K51&".png" -> D:\1. Pozos\11. Noviembre\4. DT-96\images\sec_max_res_T50.png | AS51: =Path&"images\"&$K51&".emf" -> D:\1. Pozos\11. Noviembre\4. DT-96\images\50.emf | AT51: =Path&"images\GraficaIntegradaT"&$K51&".png" -> D:\1. Pozos\11. Noviembre\4. DT-96\images\GraficaIntegradaT50.png
A52: =Pozo -> Well-1 | B52: =campo -> Exploratorio | C52: =Pais -> Colombia | D52: =Departamento -> State | E52: =company -> Ecopetrol | F52: Expro | G52: =Logdate -> 24/5/2022 | H52: 7 | I52: 6.366 | J52: =(H52-I52)/2 -> 0.317 | K52: 51 | L52: 1989.812 | M52: 2029.629 | N52: 39.817 | O52: 6.3360004 | P52: 1990.6999 | Q52: 0.34249997 | R52: 10.511519 | S52: 2029.6 | T52: 0.30148816 | U52: 6.4580002 | V52: 2029.6 | W52: 0.27099991 | X52: 14.511046 | Y52: =IF((1-AO52)<20%,"I",IF((1-AO52)<40%,"II",IF((1-AO52)<60%,"III",IF((1-AO52)<80%,"IV","V")))) -> I | Z52: =+((J52-W52)/J52)*100 -> 14.51107 | AA52: =+((U52/O52)-1)*100 -> 1.9255008 | AB52: =+(((U52-(T52-W52))/O52)-1)*100 -> 1.44431 | AC52: =+(100-Z52)/100 -> 0.8548893 | AD52: =IF(AB52>=0.5,(1-(0.05*(AB52-0.5))),1) -> 0.9527845 | AE52: =ROUND(AC52*AD52,2) -> 0.81 | AF52: 6340 | AG52: 3830 | AH52: =AK52/100 -> 0.012755544 | AI52: =+AC52*AF52 -> 5419.9982 | AJ52: =+AE52*AG52 -> 3102.3 | AK52: 1.2755544 | AL52: 1990.5 | AM52: =IF((AH52)<2%,"I",IF((AH52)<5%,"II","III")) -> I | AO52: =((100*W52)/J52)% -> 0.8548893 | AP52: =IF(Y52="I","Daño del 0-15%",IF(Y52="II","Daño del 15-25%",IF(Y52="III","Daño del 25-50%","Daño del 50-100%"))) -> Daño del 0-15% | AQ52: =Path&"images\sec_max_pen_T"&$K52&".png" -> D:\1. Pozos\11. Noviembre\4. DT-96\images\sec_max_pen_T51.png | AR52: =Path&"images\sec_max_res_T"&$K52&".png" -> D:\1. Pozos\11. Noviembre\4. DT-96\images\sec_max_res_T51.png | AS52: =Path&"images\"&$K52&".emf" -> D:\1. Pozos\11. Noviembre\4. DT-96\images\51.emf | AT52: =Path&"images\GraficaIntegradaT"&$K52&".png" -> D:\1. Pozos\11. Noviembre\4. DT-96\images\GraficaIntegradaT51.png
A53: =Pozo -> Well-1 | B53: =campo -> Exploratorio | C53: =Pais -> Colombia | D53: =Departamento -> State | E53: =company -> Ecopetrol | F53: Expro | G53: =Logdate -> 24/5/2022 | H53: 7 | I53: 6.366 | J53: =(H53-I53)/2 -> 0.317 | K53: 52 | L53: 2031.129 | M53: 2072.104 | N53: 40.976 | O53: 6.3240004 | P53: 2070.8999 | Q53: 0.34949994 | R53: 7.4318337 | S53: 2072.1001 | T53: 0.30331206 | U53: 6.4790001 | V53: 2061.8999 | W53: 0.26049995 | X53: 17.823336 | Y53: =IF((1-AO53)<20%,"I",IF((1-AO53)<40%,"II",IF((1-AO53)<60%,"III",IF((1-AO53)<80%,"IV","V")))) -> I | Z53: =+((J53-W53)/J53)*100 -> 17.823358 | AA53: =+((U53/O53)-1)*100 -> 2.450976 | AB53: =+(((U53-(T53-W53))/O53)-1)*100 -> 1.7739977 | AC53: =+(100-Z53)/100 -> 0.82176642 | AD53: =IF(AB53>=0.5,(1-(0.05*(AB53-0.5))),1) -> 0.93630011 | AE53: =ROUND(AC53*AD53,2) -> 0.77 | AF53: 6340 | AG53: 3830 | AH53: =AK53/100 -> 0.021840906 | AI53: =+AC53*AF53 -> 5209.9991 | AJ53: =+AE53*AG53 -> 2949.1 | AK53: 2.1840906 | AL53: 2070.8999 | AM53: =IF((AH53)<2%,"I",IF((AH53)<5%,"II","III")) -> II | AO53: =((100*W53)/J53)% -> 0.82176642 | AP53: =IF(Y53="I","Daño del 0-15%",IF(Y53="II","Daño del 15-25%",IF(Y53="III","Daño del 25-50%","Daño del 50-100%"))) -> Daño del 0-15% | AQ53: =Path&"images\sec_max_pen_T"&$K53&".png" -> D:\1. Pozos\11. Noviembre\4. DT-96\images\sec_max_pen_T52.png | AR53: =Path&"images\sec_max_res_T"&$K53&".png" -> D:\1. Pozos\11. Noviembre\4. DT-96\images\sec_max_res_T52.png | AS53: =Path&"images\"&$K53&".emf" -> D:\1. Pozos\11. Noviembre\4. DT-96\images\52.emf | AT53: =Path&"images\GraficaIntegradaT"&$K53&".png" -> D:\1. Pozos\11. Noviembre\4. DT-96\images\GraficaIntegradaT52.png
A54: =Pozo -> Well-1 | B54: =campo -> Exploratorio | C54: =Pais -> Colombia | D54: =Departamento -> State | E54: =company -> Ecopetrol | F54: Expro | G54: =Logdate -> 24/5/2022 | H54: 7 | I54: 6.366 | J54: =(H54-I54)/2 -> 0.317 | K54: 53 | L54: 2073.604 | M54: 2113.615 | N54: 40.01 | O54: 6.3480005 | P54: 2102.8 | Q54: 0.33450007 | R54: 6.3084869 | S54: 2111.7 | T54: 0.29959941 | U54: 6.4619999 | V54: 2076.3999 | W54: 0.26900005 | X54: 15.141915 | Y54: =IF((1-AO54)<20%,"I",IF((1-AO54)<40%,"II",IF((1-AO54)<60%,"III",IF((1-AO54)<80%,"IV","V")))) -> I | Z54: =+((J54-W54)/J54)*100 -> 15.141939 | AA54: =+((U54/O54)-1)*100 -> 1.795831 | AB54: =+(((U54-(T54-W54))/O54)-1)*100 -> 1.3137996 | AC54: =+(100-Z54)/100 -> 0.84858061 | AD54: =IF(AB54>=0.5,(1-(0.05*(AB54-0.5))),1) -> 0.95931002 | AE54: =ROUND(AC54*AD54,2) -> 0.81 | AF54: 6340 | AG54: 3830 | AH54: =AK54/100 -> 0.013668717 | AI54: =+AC54*AF54 -> 5380.0011 | AJ54: =+AE54*AG54 -> 3102.3 | AK54: 1.3668717 | AL54: 2103.3 | AM54: =IF((AH54)<2%,"I",IF((AH54)<5%,"II","III")) -> I | AO54: =((100*W54)/J54)% -> 0.84858061 | AP54: =IF(Y54="I","Daño del 0-15%",IF(Y54="II","Daño del 15-25%",IF(Y54="III","Daño del 25-50%","Daño del 50-100%"))) -> Daño del 0-15% | AQ54: =Path&"images\sec_max_pen_T"&$K54&".png" -> D:\1. Pozos\11. Noviembre\4. DT-96\images\sec_max_pen_T53.png | AR54: =Path&"images\sec_max_res_T"&$K54&".png" -> D:\1. Pozos\11. Noviembre\4. DT-96\images\sec_max_res_T53.png | AS54: =Path&"images\"&$K54&".emf" -> D:\1. Pozos\11. Noviembre\4. DT-96\images\53.emf | AT54: =Path&"images\GraficaIntegradaT"&$K54&".png" -> D:\1. Pozos\11. Noviembre\4. DT-96\images\GraficaIntegradaT53.png
A55: =Pozo -> Well-1 | B55: =campo -> Exploratorio | C55: =Pais -> Colombia | D55: =Departamento -> State | E55: =company -> Ecopetrol | F55: Expro | G55: =Logdate -> 24/5/2022 | H55: 7 | I55: 6.366 | J55: =(H55-I55)/2 -> 0.317 | K55: 54 | L55: 2115.115 | M55: 2156.476 | N55: 41.362 | O55: 6.3440003 | P55: 2115.8 | Q55: 0.33400011 | R55: 12.641336 | S55: 2156.5 | T55: 0.30179071 | U55: 6.4720001 | V55: 2116.2 | W55: 0.26399994 | X55: 16.719238 | Y55: =IF((1-AO55)<20%,"I",IF((1-AO55)<40%,"II",IF((1-AO55)<60%,"III",IF((1-AO55)<80%,"IV","V")))) -> I | Z55: =+((J55-W55)/J55)*100 -> 16.719262 | AA55: =+((U55/O55)-1)*100 -> 2.0176509 | AB55: =+(((U55-(T55-W55))/O55)-1)*100 -> 1.4219578 | AC55: =+(100-Z55)/100 -> 0.83280738 | AD55: =IF(AB55>=0.5,(1-(0.05*(AB55-0.5))),1) -> 0.95390211 | AE55: =ROUND(AC55*AD55,2) -> 0.79 | AF55: 6340 | AG55: 3830 | AH55: =AK55/100 -> 0.015953401 | AI55: =+AC55*AF55 -> 5279.9988 | AJ55: =+AE55*AG55 -> 3025.7 | AK55: 1.5953401 | AL55: 2116.2 | AM55: =IF((AH55)<2%,"I",IF((AH55)<5%,"II","III")) -> I | AO55: =((100*W55)/J55)% -> 0.83280738 | AP55: =IF(Y55="I","Daño del 0-15%",IF(Y55="II","Daño del 15-25%",IF(Y55="III","Daño del 25-50%","Daño del 50-100%"))) -> Daño del 0-15% | AQ55: =Path&"images\sec_max_pen_T"&$K55&".png" -> D:\1. Pozos\11. Noviembre\4. DT-96\images\sec_max_pen_T54.png | AR55: =Path&"images\sec_max_res_T"&$K55&".png" -> D:\1. Pozos\11. Noviembre\4. DT-96\images\sec_max_res_T54.png | AS55: =Path&"images\"&$K55&".emf" -> D:\1. Pozos\11. Noviembre\4. DT-96\images\54.emf | AT55: =Path&"images\GraficaIntegradaT"&$K55&".png" -> D:\1. Pozos\11. Noviembre\4. DT-96\images\GraficaIntegradaT54.png
A56: =Pozo -> Well-1 | B56: =campo -> Exploratorio | C56: =Pais -> Colombia | D56: =Departamento -> State | E56: =company -> Ecopetrol | F56: Expro | G56: =Logdate -> 24/5/2022 | H56: 7 | I56: 6.366 | J56: =(H56-I56)/2 -> 0.317 | K56: 55 | L56: 2157.976 | M56: 2198.373 | N56: 40.396 | O56: 6.3305001 | P56: 2167.5 | Q56: 0.34299993 | R56: 5.1580725 | S56: 2175.6001 | T56: 0.30296612 | U56: 6.467 | V56: 2167.3999 | W56: 0.2665 | X56: 15.930577 | Y56: =IF((1-AO56)<20%,"I",IF((1-AO56)<40%,"II",IF((1-AO56)<60%,"III",IF((1-AO56)<80%,"IV","V")))) -> I | Z56: =+((J56-W56)/J56)*100 -> 15.930601 | AA56: =+((U56/O56)-1)*100 -> 2.1562258 | AB56: =+(((U56-(T56-W56))/O56)-1)*100 -> 1.5801873 | AC56: =+(100-Z56)/100 -> 0.84069399 | AD56: =IF(AB56>=0.5,(1-(0.05*(AB56-0.5))),1) -> 0.94599064 | AE56: =ROUND(AC56*AD56,2) -> 0.8 | AF56: 6340 | AG56: 3830 | AH56: =AK56/100 -> 0.017007418 | AI56: =+AC56*AF56 -> 5329.9999 | AJ56: =+AE56*AG56 -> 3064 | AK56: 1.7007418 | AL56: 2167.3999 | AM56: =IF((AH56)<2%,"I",IF((AH56)<5%,"II","III")) -> I | AO56: =((100*W56)/J56)% -> 0.84069399 | AP56: =IF(Y56="I","Daño del 0-15%",IF(Y56="II","Daño del 15-25%",IF(Y56="III","Daño del 25-50%","Daño del 50-100%"))) -> Daño del 0-15% | AQ56: =Path&"images\sec_max_pen_T"&$K56&".png" -> D:\1. Pozos\11. Noviembre\4. DT-96\images\sec_max_pen_T55.png | AR56: =Path&"images\sec_max_res_T"&$K56&".png" -> D:\1. Pozos\11. Noviembre\4. DT-96\images\sec_max_res_T55.png | AS56: =Path&"images\"&$K56&".emf" -> D:\1. Pozos\11. Noviembre\4. DT-96\images\55.emf | AT56: =Path&"images\GraficaIntegradaT"&$K56&".png" -> D:\1. Pozos\11. Noviembre\4. DT-96\images\GraficaIntegradaT55.png
A57: =Pozo -> Well-1 | B57: =campo -> Exploratorio | C57: =Pais -> Colombia | D57: =Departamento -> State | E57: =company -> Ecopetrol | F57: Expro | G57: =Logdate -> 24/5/2022 | H57: 7 | I57: 6.366 | J57: =(H57-I57)/2 -> 0.317 | K57: 56 | L57: 2199.873 | M57: 2240.848 | N57: 40.976 | O57: 6.3360004 | P57: 2239 | Q57: 0.3434999 | R57: 5.7721472 | S57: 2240.8 | T57: 0.30270362 | U57: 6.4759998 | V57: 2238.6001 | W57: 0.26200008 | X57: 17.350109 | Y57: =IF((1-AO57)<20%,"I",IF((1-AO57)<40%,"II",IF((1-AO57)<60%,"III",IF((1-AO57)<80%,"IV","V")))) -> I | Z57: =+((J57-W57)/J57)*100 -> 17.350131 | AA57: =+((U57/O57)-1)*100 -> 2.2095862 | AB57: =+(((U57-(T57-W57))/O57)-1)*100 -> 1.5671693 | AC57: =+(100-Z57)/100 -> 0.82649869 | AD57: =IF(AB57>=0.5,(1-(0.05*(AB57-0.5))),1) -> 0.94664153 | AE57: =ROUND(AC57*AD57,2) -> 0.78 | AF57: 6340 | AG57: 3830 | AH57: =AK57/100 -> 0.018416857 | AI57: =+AC57*AF57 -> 5240.0017 | AJ57: =+AE57*AG57 -> 2987.4 | AK57: 1.8416857 | AL57: 2238.8999 | AM57: =IF((AH57)<2%,"I",IF((AH57)<5%,"II","III")) -> I | AO57: =((100*W57)/J57)% -> 0.82649869 | AP57: =IF(Y57="I","Daño del 0-15%",IF(Y57="II","Daño del 15-25%",IF(Y57="III","Daño del 25-50%","Daño del 50-100%"))) -> Daño del 0-15% | AQ57: =Path&"images\sec_max_pen_T"&$K57&".png" -> D:\1. Pozos\11. Noviembre\4. DT-96\images\sec_max_pen_T56.png | AR57: =Path&"images\sec_max_res_T"&$K57&".png" -> D:\1. Pozos\11. Noviembre\4. DT-96\images\sec_max_res_T56.png | AS57: =Path&"images\"&$K57&".emf" -> D:\1. Pozos\11. Noviembre\4. DT-96\images\56.emf | AT57: =Path&"images\GraficaIntegradaT"&$K57&".png" -> D:\1. Pozos\11. Noviembre\4. DT-96\images\GraficaIntegradaT56.png
A58: =Pozo -> Well-1 | B58: =campo -> Exploratorio | C58: =Pais -> Colombia | D58: =Departamento -> State | E58: =company -> Ecopetrol | F58: Expro | G58: =Logdate -> 24/5/2022 | H58: 7 | I58: 6.366 | J58: =(H58-I58)/2 -> 0.317 | K58: 57 | L58: 2242.348 | M58: 2281.973 | N58: 39.624 | O58: 6.1860003 | P58: 2265.6001 | Q58: 0.41650009 | R58: 13.011867 | S58: 2265.5 | T58: 0.30305028 | U58: 6.6830001 | V58: 2272 | W58: 0.15849996 | X58: 50 | Y58: =IF((1-AO58)<20%,"I",IF((1-AO58)<40%,"II",IF((1-AO58)<60%,"III",IF((1-AO58)<80%,"IV","V")))) -> III | Z58: =+((J58-W58)/J58)*100 -> 50.000014 | AA58: =+((U58/O58)-1)*100 -> 8.0342663 | AB58: =+(((U58-(T58-W58))/O58)-1)*100 -> 5.6975331 | AC58: =+(100-Z58)/100 -> 0.49999986 | AD58: =IF(AB58>=0.5,(1-(0.05*(AB58-0.5))),1) -> 0.74012335 | AE58: =ROUND(AC58*AD58,2) -> 0.37 | AF58: 6340 | AG58: 3830 | AH58: =AK58/100 -> 0.067000837 | AI58: =+AC58*AF58 -> 3169.9991 | AJ58: =+AE58*AG58 -> 1417.1 | AK58: 6.7000837 | AL58: 2265.3 | AM58: =IF((AH58)<2%,"I",IF((AH58)<5%,"II","III")) -> III | AN58: Perf. | AO58: =((100*W58)/J58)% -> 0.49999986 | AP58: =IF(Y58="I","Daño del 0-15%",IF(Y58="II","Daño del 15-25%",IF(Y58="III","Daño del 25-50%","Daño del 50-100%"))) -> Daño del 25-50% | AQ58: =Path&"images\sec_max_pen_T"&$K58&".png" -> D:\1. Pozos\11. Noviembre\4. DT-96\images\sec_max_pen_T57.png | AR58: =Path&"images\sec_max_res_T"&$K58&".png" -> D:\1. Pozos\11. Noviembre\4. DT-96\images\sec_max_res_T57.png | AS58: =Path&"images\"&$K58&".emf" -> D:\1. Pozos\11. Noviembre\4. DT-96\images\57.emf | AT58: =Path&"images\GraficaIntegradaT"&$K58&".png" -> D:\1. Pozos\11. Noviembre\4. DT-96\images\GraficaIntegradaT57.png
A59: =Pozo -> Well-1 | B59: =campo -> Exploratorio | C59: =Pais -> Colombia | D59: =Departamento -> State | E59: =company -> Ecopetrol | F59: Expro | G59: =Logdate -> 24/5/2022 | H59: 7 | I59: 6.366 | J59: =(H59-I59)/2 -> 0.317 | K59: 58 | L59: 2283.473 | M59: 2324.255 | N59: 40.783 | O59: 6.2935004 | P59: 2307.8999 | Q59: 0.36150003 | R59: 8.2285747 | S59: 2307.8999 | T59: 0.30048251 | U59: 6.52 | V59: 2306 | W59: 0.24000001 | X59: 24.290197 | Y59: =IF((1-AO59)<20%,"I",IF((1-AO59)<40%,"II",IF((1-AO59)<60%,"III",IF((1-AO59)<80%,"IV","V")))) -> II | Z59: =+((J59-W59)/J59)*100 -> 24.290218 | AA59: =+((U59/O59)-1)*100 -> 3.5989441 | AB59: =+(((U59-(T59-W59))/O59)-1)*100 -> 2.6379129 | AC59: =+(100-Z59)/100 -> 0.75709782 | AD59: =IF(AB59>=0.5,(1-(0.05*(AB59-0.5))),1) -> 0.89310436 | AE59: =ROUND(AC59*AD59,2) -> 0.68 | AF59: 6340 | AG59: 3830 | AH59: =AK59/100 -> 0.035403571 | AI59: =+AC59*AF59 -> 4800.0002 | AJ59: =+AE59*AG59 -> 2604.4 | AK59: 3.5403571 | AL59: 2307.8999 | AM59: =IF((AH59)<2%,"I",IF((AH59)<5%,"II","III")) -> II | AO59: =((100*W59)/J59)% -> 0.75709782 | AP59: =IF(Y59="I","Daño del 0-15%",IF(Y59="II","Daño del 15-25%",IF(Y59="III","Daño del 25-50%","Daño del 50-100%"))) -> Daño del 15-25% | AQ59: =Path&"images\sec_max_pen_T"&$K59&".png" -> D:\1. Pozos\11. Noviembre\4. DT-96\images\sec_max_pen_T58.png | AR59: =Path&"images\sec_max_res_T"&$K59&".png" -> D:\1. Pozos\11. Noviembre\4. DT-96\images\sec_max_res_T58.png | AS59: =Path&"images\"&$K59&".emf" -> D:\1. Pozos\11. Noviembre\4. DT-96\images\58.emf | AT59: =Path&"images\GraficaIntegradaT"&$K59&".png" -> D:\1. Pozos\11. Noviembre\4. DT-96\images\GraficaIntegradaT58.png
A60: =Pozo -> Well-1 | B60: =campo -> Exploratorio | C60: =Pais -> Colombia | D60: =Departamento -> State | E60: =company -> Ecopetrol | F60: Expro | G60: =Logdate -> 24/5/2022 | H60: 7 | I60: 6.366 | J60: =(H60-I60)/2 -> 0.317 | K60: 59 | L60: 2325.755 | M60: 2365.958 | N60: 40.203 | O60: 6.3040004 | P60: 2332.6001 | Q60: 0.36350012 | R60: 9.2260141 | S60: 2331.1001 | T60: 0.29895472 | U60: 6.8010001 | V60: 2331.1001 | W60: 0.099499941 | X60: 68.611992 | Y60: =IF((1-AO60)<20%,"I",IF((1-AO60)<40%,"II",IF((1-AO60)<60%,"III",IF((1-AO60)<80%,"IV","V")))) -> IV | Z60: =+((J60-W60)/J60)*100 -> 68.612006 | AA60: =+((U60/O60)-1)*100 -> 7.8838786 | AB60: =+(((U60-(T60-W60))/O60)-1)*100 -> 4.7199387 | AC60: =+(100-Z60)/100 -> 0.31387994 | AD60: =IF(AB60>=0.5,(1-(0.05*(AB60-0.5))),1) -> 0.78900306 | AE60: =ROUND(AC60*AD60,2) -> 0.25 | AF60: 6340 | AG60: 3830 | AH60: =AK60/100 -> 0.026904461 | AI60: =+AC60*AF60 -> 1989.9988 | AJ60: =+AE60*AG60 -> 957.5 | AK60: 2.6904461 | AL60: 2332.6001 | AM60: =IF((AH60)<2%,"I",IF((AH60)<5%,"II","III")) -> II | AN60: Perf. | AO60: =((100*W60)/J60)% -> 0.31387994 | AP60: =IF(Y60="I","Daño del 0-15%",IF(Y60="II","Daño del 15-25%",IF(Y60="III","Daño del 25-50%","Daño del 50-100%"))) -> Daño del 50-100% | AQ60: =Path&"images\sec_max_pen_T"&$K60&".png" -> D:\1. Pozos\11. Noviembre\4. DT-96\images\sec_max_pen_T59.png | AR60: =Path&"images\sec_max_res_T"&$K60&".png" -> D:\1. Pozos\11. Noviembre\4. DT-96\images\sec_max_res_T59.png | AS60: =Path&"images\"&$K60&".emf" -> D:\1. Pozos\11. Noviembre\4. DT-96\images\59.emf | AT60: =Path&"images\GraficaIntegradaT"&$K60&".png" -> D:\1. Pozos\11. Noviembre\4. DT-96\images\GraficaIntegradaT59.png
A61: =Pozo -> Well-1 | B61: =campo -> Exploratorio | C61: =Pais -> Colombia | D61: =Departamento -> State | E61: =company -> Ecopetrol | F61: Expro | G61: =Logdate -> 24/5/2022 | H61: 7 | I61: 6.366 | J61: =(H61-I61)/2 -> 0.317 | K61: 60 | L61: 2367.458 | M61: 2403.221 | N61: 35.763 | O61: 6.3415003 | P61: 2373.1001 | Q61: 0.34249997 | R61: 12.555916 | S61: 2367.5 | T61: 0.300596 | U61: 6.4759998 | V61: 2373.3 | W61: 0.26200008 | X61: 17.350109 | Y61: =IF((1-AO61)<20%,"I",IF((1-AO61)<40%,"II",IF((1-AO61)<60%,"III",IF((1-AO61)<80%,"IV","V")))) -> I | Z61: =+((J61-W61)/J61)*100 -> 17.350131 | AA61: =+((U61/O61)-1)*100 -> 2.1209421 | AB61: =+(((U61-(T61-W61))/O61)-1)*100 -> 1.5123178 | AC61: =+(100-Z61)/100 -> 0.82649869 | AD61: =IF(AB61>=0.5,(1-(0.05*(AB61-0.5))),1) -> 0.94938411 | AE61: =ROUND(AC61*AD61,2) -> 0.78 | AF61: 6340 | AG61: 3830 | AH61: =AK61/100 -> 0.01661924 | AI61: =+AC61*AF61 -> 5240.0017 | AJ61: =+AE61*AG61 -> 2987.4 | AK61: 1.661924 | AL61: 2375.7 | AM61: =IF((AH61)<2%,"I",IF((AH61)<5%,"II","III")) -> I | AO61: =((100*W61)/J61)% -> 0.82649869 | AP61: =IF(Y61="I","Daño del 0-15%",IF(Y61="II","Daño del 15-25%",IF(Y61="III","Daño del 25-50%","Daño del 50-100%"))) -> Daño del 0-15% | AQ61: =Path&"images\sec_max_pen_T"&$K61&".png" -> D:\1. Pozos\11. Noviembre\4. DT-96\images\sec_max_pen_T60.png | AR61: =Path&"images\sec_max_res_T"&$K61&".png" -> D:\1. Pozos\11. Noviembre\4. DT-96\images\sec_max_res_T60.png | AS61: =Path&"images\"&$K61&".emf" -> D:\1. Pozos\11. Noviembre\4. DT-96\images\60.emf | AT61: =Path&"images\GraficaIntegradaT"&$K61&".png" -> D:\1. Pozos\11. Noviembre\4. DT-96\images\GraficaIntegradaT60.png
A62: =Pozo -> Well-1 | B62: =campo -> Exploratorio | C62: =Pais -> Colombia | D62: =Departamento -> State | E62: =company -> Ecopetrol | F62: Expro | G62: =Logdate -> 24/5/2022 | H62: 7 | I62: 6.366 | J62: =(H62-I62)/2 -> 0.317 | K62: 61 | L62: 2404.721 | M62: 2444.538 | N62: 39.817 | O62: 6.2500005 | P62: 2425.6001 | Q62: 0.44499993 | R62: 8.381855 | S62: 2404.7 | T62: 0.30227518 | U62: 6.481 | V62: 2425.7 | W62: 0.25950003 | X62: 18.138771 | Y62: =IF((1-AO62)<20%,"I",IF((1-AO62)<40%,"II",IF((1-AO62)<60%,"III",IF((1-AO62)<80%,"IV","V")))) -> I | Z62: =+((J62-W62)/J62)*100 -> 18.138793 | AA62: =+((U62/O62)-1)*100 -> 3.6959912 | AB62: =+(((U62-(T62-W62))/O62)-1)*100 -> 3.0115888 | AC62: =+(100-Z62)/100 -> 0.81861207 | AD62: =IF(AB62>=0.5,(1-(0.05*(AB62-0.5))),1) -> 0.87442056 | AE62: =ROUND(AC62*AD62,2) -> 0.72 | AF62: 6340 | AG62: 3830 | AH62: =AK62/100 -> 0.016339362 | AI62: =+AC62*AF62 -> 5190.0005 | AJ62: =+AE62*AG62 -> 2757.6 | AK62: 1.6339362 | AL62: 2431.3 | AM62: =IF((AH62)<2%,"I",IF((AH62)<5%,"II","III")) -> I | AO62: =((100*W62)/J62)% -> 0.81861207 | AP62: =IF(Y62="I","Daño del 0-15%",IF(Y62="II","Daño del 15-25%",IF(Y62="III","Daño del 25-50%","Daño del 50-100%"))) -> Daño del 0-15% | AQ62: =Path&"images\sec_max_pen_T"&$K62&".png" -> D:\1. Pozos\11. Noviembre\4. DT-96\images\sec_max_pen_T61.png | AR62: =Path&"images\sec_max_res_T"&$K62&".png" -> D:\1. Pozos\11. Noviembre\4. DT-96\images\sec_max_res_T61.png | AS62: =Path&"images\"&$K62&".emf" -> D:\1. Pozos\11. Noviembre\4. DT-96\images\61.emf | AT62: =Path&"images\GraficaIntegradaT"&$K62&".png" -> D:\1. Pozos\11. Noviembre\4. DT-96\images\GraficaIntegradaT61.png
A63: =Pozo -> Well-1 | B63: =campo -> Exploratorio | C63: =Pais -> Colombia | D63: =Departamento -> State | E63: =company -> Ecopetrol | F63: Expro | G63: =Logdate -> 24/5/2022 | H63: 7 | I63: 6.366 | J63: =(H63-I63)/2 -> 0.317 | K63: 62 | L63: 2446.038 | M63: 2485.662 | N63: 39.624 | O63: 6.3045001 | P63: 2485.2 | Q63: 0.36249995 | R63: 12.089598 | S63: 2446 | T63: 0.29811406 | U63: 6.7779999 | V63: 2447.3999 | W63: 0.11100006 | X63: 64.9842 | Y63: =IF((1-AO63)<20%,"I",IF((1-AO63)<40%,"II",IF((1-AO63)<60%,"III",IF((1-AO63)<80%,"IV","V")))) -> IV | Z63: =+((J63-W63)/J63)*100 -> 64.984208 | AA63: =+((U63/O63)-1)*100 -> 7.5105048 | AB63: =+(((U63-(T63-W63))/O63)-1)*100 -> 4.5425613 | AC63: =+(100-Z63)/100 -> 0.35015792 | AD63: =IF(AB63>=0.5,(1-(0.05*(AB63-0.5))),1) -> 0.79787194 | AE63: =ROUND(AC63*AD63,2) -> 0.28 | AF63: 6340 | AG63: 3830 | AH63: =AK63/100 -> 0.027968431 | AI63: =+AC63*AF63 -> 2220.0012 | AJ63: =+AE63*AG63 -> 1072.4 | AK63: 2.7968431 | AL63: 2485.1001 | AM63: =IF((AH63)<2%,"I",IF((AH63)<5%,"II","III")) -> II | AN63: Perf. | AO63: =((100*W63)/J63)% -> 0.35015792 | AP63: =IF(Y63="I","Daño del 0-15%",IF(Y63="II","Daño del 15-25%",IF(Y63="III","Daño del 25-50%","Daño del 50-100%"))) -> Daño del 50-100% | AQ63: =Path&"images\sec_max_pen_T"&$K63&".png" -> D:\1. Pozos\11. Noviembre\4. DT-96\images\sec_max_pen_T62.png | AR63: =Path&"images\sec_max_res_T"&$K63&".png" -> D:\1. Pozos\11. Noviembre\4. DT-96\images\sec_max_res_T62.png | AS63: =Path&"images\"&$K63&".emf" -> D:\1. Pozos\11. Noviembre\4. DT-96\images\62.emf | AT63: =Path&"images\GraficaIntegradaT"&$K63&".png" -> D:\1. Pozos\11. Noviembre\4. DT-96\images\GraficaIntegradaT62.png
A64: =Pozo -> Well-1 | B64: =campo -> Exploratorio | C64: =Pais -> Colombia | D64: =Departamento -> State | E64: =company -> Ecopetrol | F64: Expro | G64: =Logdate -> 24/5/2022 | H64: 7 | I64: 6.366 | J64: =(H64-I64)/2 -> 0.317 | K64: 63 | L64: 2487.162 | M64: 2526.98 | N64: 39.817 | O64: 6.3130002 | P64: 2491.6001 | Q64: 0.35400009 | R64: 7.9980431 | S64: 2487.2 | T64: 0.30117536 | U64: 6.513 | V64: 2495.5 | W64: 0.24349999 | X64: 23.1861 | Y64: =IF((1-AO64)<20%,"I",IF((1-AO64)<40%,"II",IF((1-AO64)<60%,"III",IF((1-AO64)<80%,"IV","V")))) -> II | Z64: =+((J64-W64)/J64)*100 -> 23.186122 | AA64: =+((U64/O64)-1)*100 -> 3.1680628 | AB64: =+(((U64-(T64-W64))/O64)-1)*100 -> 2.2544661 | AC64: =+(100-Z64)/100 -> 0.76813878 | AD64: =IF(AB64>=0.5,(1-(0.05*(AB64-0.5))),1) -> 0.9122767 | AE64: =ROUND(AC64*AD64,2) -> 0.7 | AF64: 6340 | AG64: 3830 | AH64: =AK64/100 -> 0.02675045 | AI64: =+AC64*AF64 -> 4869.9999 | AJ64: =+AE64*AG64 -> 2681 | AK64: 2.675045 | AL64: 2495.6001 | AM64: =IF((AH64)<2%,"I",IF((AH64)<5%,"II","III")) -> II | AO64: =((100*W64)/J64)% -> 0.76813878 | AP64: =IF(Y64="I","Daño del 0-15%",IF(Y64="II","Daño del 15-25%",IF(Y64="III","Daño del 25-50%","Daño del 50-100%"))) -> Daño del 15-25% | AQ64: =Path&"images\sec_max_pen_T"&$K64&".png" -> D:\1. Pozos\11. Noviembre\4. DT-96\images\sec_max_pen_T63.png | AR64: =Path&"images\sec_max_res_T"&$K64&".png" -> D:\1. Pozos\11. Noviembre\4. DT-96\images\sec_max_res_T63.png | AS64: =Path&"images\"&$K64&".emf" -> D:\1. Pozos\11. Noviembre\4. DT-96\images\63.emf | AT64: =Path&"images\GraficaIntegradaT"&$K64&".png" -> D:\1. Pozos\11. Noviembre\4. DT-96\images\GraficaIntegradaT63.png
A65: =Pozo -> Well-1 | B65: =campo -> Exploratorio | C65: =Pais -> Colombia | D65: =Departamento -> State | E65: =company -> Ecopetrol | F65: Expro | G65: =Logdate -> 24/5/2022 | H65: 7 | I65: 6.366 | J65: =(H65-I65)/2 -> 0.317 | K65: 64 | L65: 2528.48 | M65: 2565.98 | N65: 37.5 | O65: 6.2870002 | P65: 2554.3 | Q65: 0.37100005 | R65: 7.6962113 | S65: 2554.2 | T65: 0.30067825 | U65: 6.5149999 | V65: 2554.1001 | W65: 0.24250007 | X65: 23.501535 | Y65: =IF((1-AO65)<20%,"I",IF((1-AO65)<40%,"II",IF((1-AO65)<60%,"III",IF((1-AO65)<80%,"IV","V")))) -> II | Z65: =+((J65-W65)/J65)*100 -> 23.501556 | AA65: =+((U65/O65)-1)*100 -> 3.6265259 | AB65: =+(((U65-(T65-W65))/O65)-1)*100 -> 2.7011532 | AC65: =+(100-Z65)/100 -> 0.76498444 | AD65: =IF(AB65>=0.5,(1-(0.05*(AB65-0.5))),1) -> 0.88994234 | AE65: =ROUND(AC65*AD65,2) -> 0.68 | AF65: 6340 | AG65: 3830 | AH65: =AK65/100 -> 0.03354924 | AI65: =+AC65*AF65 -> 4850.0013 | AJ65: =+AE65*AG65 -> 2604.4 | AK65: 3.354924 | AL65: 2554.2 | AM65: =IF((AH65)<2%,"I",IF((AH65)<5%,"II","III")) -> II | AO65: =((100*W65)/J65)% -> 0.76498444 | AP65: =IF(Y65="I","Daño del 0-15%",IF(Y65="II","Daño del 15-25%",IF(Y65="III","Daño del 25-50%","Daño del 50-100%"))) -> Daño del 15-25% | AQ65: =Path&"images\sec_max_pen_T"&$K65&".png" -> D:\1. Pozos\11. Noviembre\4. DT-96\images\sec_max_pen_T64.png | AR65: =Path&"images\sec_max_res_T"&$K65&".png" -> D:\1. Pozos\11. Noviembre\4. DT-96\images\sec_max_res_T64.png | AS65: =Path&"images\"&$K65&".emf" -> D:\1. Pozos\11. Noviembre\4. DT-96\images\64.emf | AT65: =Path&"images\GraficaIntegradaT"&$K65&".png" -> D:\1. Pozos\11. Noviembre\4. DT-96\images\GraficaIntegradaT64.png
A66: =Pozo -> Well-1 | B66: =campo -> Exploratorio | C66: =Pais -> Colombia | D66: =Departamento -> State | E66: =company -> Ecopetrol | F66: Expro | G66: =Logdate -> 24/5/2022 | H66: 7 | I66: 6.366 | J66: =(H66-I66)/2 -> 0.317 | K66: 65 | L66: 2567.48 | M66: 2604.98 | N66: 37.5 | O66: 6.3070002 | P66: 2587.3 | Q66: 0.35599995 | R66: 12.548784 | S66: 2567.6001 | T66: 0.29626298 | U66: 6.7880001 | V66: 2600.8999 | W66: 0.10599995 | X66: 66.561523 | Y66: =IF((1-AO66)<20%,"I",IF((1-AO66)<40%,"II",IF((1-AO66)<60%,"III",IF((1-AO66)<80%,"IV","V")))) -> IV | Z66: =+((J66-W66)/J66)*100 -> 66.561531 | AA66: =+((U66/O66)-1)*100 -> 7.6264458 | AB66: =+(((U66-(T66-W66))/O66)-1)*100 -> 4.6097496 | AC66: =+(100-Z66)/100 -> 0.33438469 | AD66: =IF(AB66>=0.5,(1-(0.05*(AB66-0.5))),1) -> 0.79451252 | AE66: =ROUND(AC66*AD66,2) -> 0.27 | AF66: 6340 | AG66: 3830 | AH66: =AK66/100 -> 0.026996963 | AI66: =+AC66*AF66 -> 2119.9989 | AJ66: =+AE66*AG66 -> 1034.1 | AK66: 2.6996963 | AL66: 2587.5 | AM66: =IF((AH66)<2%,"I",IF((AH66)<5%,"II","III")) -> II | AN66: Perf. | AO66: =((100*W66)/J66)% -> 0.33438469 | AP66: =IF(Y66="I","Daño del 0-15%",IF(Y66="II","Daño del 15-25%",IF(Y66="III","Daño del 25-50%","Daño del 50-100%"))) -> Daño del 50-100% | AQ66: =Path&"images\sec_max_pen_T"&$K66&".png" -> D:\1. Pozos\11. Noviembre\4. DT-96\images\sec_max_pen_T65.png | AR66: =Path&"images\sec_max_res_T"&$K66&".png" -> D:\1. Pozos\11. Noviembre\4. DT-96\images\sec_max_res_T65.png | AS66: =Path&"images\"&$K66&".emf" -> D:\1. Pozos\11. Noviembre\4. DT-96\images\65.emf | AT66: =Path&"images\GraficaIntegradaT"&$K66&".png" -> D:\1. Pozos\11. Noviembre\4. DT-96\images\GraficaIntegradaT65.png
A67: =Pozo -> Well-1 | B67: =campo -> Exploratorio | C67: =Pais -> Colombia | D67: =Departamento -> State | E67: =company -> Ecopetrol | F67: Expro | G67: =Logdate -> 24/5/2022 | H67: 7 | I67: 6.366 | J67: =(H67-I67)/2 -> 0.317 | K67: 66 | L67: 2606.48 | M67: 2648.035 | N67: 41.555 | O67: 6.3165002 | P67: 2614.8 | Q67: 0.34899998 | R67: 12.157076 | S67: 2648 | T67: 0.30063963 | U67: 6.7529998 | V67: 2606.8999 | W67: 0.12350011 | X67: 61.040962 | Y67: =IF((1-AO67)<20%,"I",IF((1-AO67)<40%,"II",IF((1-AO67)<60%,"III",IF((1-AO67)<80%,"IV","V")))) -> IV | Z67: =+((J67-W67)/J67)*100 -> 61.040975 | AA67: =+((U67/O67)-1)*100 -> 6.9104659 | AB67: =+(((U67-(T67-W67))/O67)-1)*100 -> 4.1060724 | AC67: =+(100-Z67)/100 -> 0.38959025 | AD67: =IF(AB67>=0.5,(1-(0.05*(AB67-0.5))),1) -> 0.81969638 | AE67: =ROUND(AC67*AD67,2) -> 0.32 | AF67: 6340 | AG67: 3830 | AH67: =AK67/100 -> 0.025258505 | AI67: =+AC67*AF67 -> 2470.0022 | AJ67: =+AE67*AG67 -> 1225.6 | AK67: 2.5258505 | AL67: 2614.8999 | AM67: =IF((AH67)<2%,"I",IF((AH67)<5%,"II","III")) -> II | AN67: Perf. | AO67: =((100*W67)/J67)% -> 0.38959025 | AP67: =IF(Y67="I","Daño del 0-15%",IF(Y67="II","Daño del 15-25%",IF(Y67="III","Daño del 25-50%","Daño del 50-100%"))) -> Daño del 50-100% | AQ67: =Path&"images\sec_max_pen_T"&$K67&".png" -> D:\1. Pozos\11. Noviembre\4. DT-96\images\sec_max_pen_T66.png | AR67: =Path&"images\sec_max_res_T"&$K67&".png" -> D:\1. Pozos\11. Noviembre\4. DT-96\images\sec_max_res_T66.png | AS67: =Path&"images\"&$K67&".emf" -> D:\1. Pozos\11. Noviembre\4. DT-96\images\66.emf | AT67: =Path&"images\GraficaIntegradaT"&$K67&".png" -> D:\1. Pozos\11. Noviembre\4. DT-96\images\GraficaIntegradaT66.png
A68: =Pozo -> Well-1 | B68: =campo -> Exploratorio | C68: =Pais -> Colombia | D68: =Departamento -> State | E68: =company -> Ecopetrol | F68: Expro | G68: =Logdate -> 24/5/2022 | H68: 7 | I68: 6.366 | J68: =(H68-I68)/2 -> 0.317 | K68: 67 | L68: 2649.535 | M68: 2688.58 | N68: 39.045 | O68: 6.3125005 | P68: 2663.3999 | Q68: 0.35100007 | R68: 6.61275 | S68: 2650.5 | T68: 0.30151653 | U68: 6.513 | V68: 2650.6001 | W68: 0.24349999 | X68: 23.1861 | Y68: =IF((1-AO68)<20%,"I",IF((1-AO68)<40%,"II",IF((1-AO68)<60%,"III",IF((1-AO68)<80%,"IV","V")))) -> II | Z68: =+((J68-W68)/J68)*100 -> 23.186122 | AA68: =+((U68/O68)-1)*100 -> 3.1762299 | AB68: =+(((U68-(T68-W68))/O68)-1)*100 -> 2.2571561 | AC68: =+(100-Z68)/100 -> 0.76813878 | AD68: =IF(AB68>=0.5,(1-(0.05*(AB68-0.5))),1) -> 0.91214219 | AE68: =ROUND(AC68*AD68,2) -> 0.7 | AF68: 6340 | AG68: 3830 | AH68: =AK68/100 -> 0.027235022 | AI68: =+AC68*AF68 -> 4869.9999 | AJ68: =+AE68*AG68 -> 2681 | AK68: 2.7235022 | AL68: 2663.3999 | AM68: =IF((AH68)<2%,"I",IF((AH68)<5%,"II","III")) -> II | AO68: =((100*W68)/J68)% -> 0.76813878 | AP68: =IF(Y68="I","Daño del 0-15%",IF(Y68="II","Daño del 15-25%",IF(Y68="III","Daño del 25-50%","Daño del 50-100%"))) -> Daño del 15-25% | AQ68: =Path&"images\sec_max_pen_T"&$K68&".png" -> D:\1. Pozos\11. Noviembre\4. DT-96\images\sec_max_pen_T67.png | AR68: =Path&"images\sec_max_res_T"&$K68&".png" -> D:\1. Pozos\11. Noviembre\4. DT-96\images\sec_max_res_T67.png | AS68: =Path&"images\"&$K68&".emf" -> D:\1. Pozos\11. Noviembre\4. DT-96\images\67.emf | AT68: =Path&"images\GraficaIntegradaT"&$K68&".png" -> D:\1. Pozos\11. Noviembre\4. DT-96\images\GraficaIntegradaT67.png
